ERROR:root:Traceback (most recent call last):
  File "D:/DC_MHA/db_handle/dbHandle.py", line 20, in __init__
    charset="utf8",ssl=ssl_set)
  File "C:\Python27\lib\site-packages\MySQLdb\__init__.py", line 81, in Connect
    return Connection(*args, **kwargs)
  File "C:\Python27\lib\site-packages\MySQLdb\connections.py", line 193, in __init__
    super(Connection, self).__init__(*args, **kwargs2)
OperationalError: (2026, 'SSL connection error')

ERROR:root:Traceback (most recent call last):
  File "D:/DC_MHA/db_handle/dbHandle.py", line 20, in __init__
    charset="utf8")
  File "C:\Python27\lib\site-packages\MySQLdb\__init__.py", line 81, in Connect
    return Connection(*args, **kwargs)
  File "C:\Python27\lib\site-packages\MySQLdb\connections.py", line 193, in __init__
    super(Connection, self).__init__(*args, **kwargs2)
OperationalError: (1045, "Access denied for user 'root'@'192.168.212.223' (using password: YES)")

ERROR:root:Traceback (most recent call last):
  File "D:/DC_MHA/db_handle/dbHandle.py", line 20, in __init__
    charset="utf8",ssl=ssl_set)
  File "C:\Python27\lib\site-packages\MySQLdb\__init__.py", line 81, in Connect
    return Connection(*args, **kwargs)
  File "C:\Python27\lib\site-packages\MySQLdb\connections.py", line 193, in __init__
    super(Connection, self).__init__(*args, **kwargs2)
OperationalError: (2026, 'SSL connection error')

ERROR:root:Traceback (most recent call last):
  File "D:/DC_MHA/db_handle/dbHandle.py", line 20, in __init__
    charset="utf8",ssl=ssl_set)
  File "C:\Python27\lib\site-packages\MySQLdb\__init__.py", line 81, in Connect
    return Connection(*args, **kwargs)
  File "C:\Python27\lib\site-packages\MySQLdb\connections.py", line 193, in __init__
    super(Connection, self).__init__(*args, **kwargs2)
OperationalError: (2026, 'SSL connection error')

ERROR:root:Traceback (most recent call last):
  File "D:/DC_MHA/db_handle/dbHandle.py", line 20, in __init__
    charset="utf8",ssl=ssl_set)
  File "C:\Python27\lib\site-packages\MySQLdb\__init__.py", line 81, in Connect
    return Connection(*args, **kwargs)
  File "C:\Python27\lib\site-packages\MySQLdb\connections.py", line 193, in __init__
    super(Connection, self).__init__(*args, **kwargs2)
OperationalError: (2026, 'SSL connection error')

ERROR:root:Traceback (most recent call last):
  File "D:/DC_MHA/db_handle/dbHandle.py", line 20, in __init__
    charset="utf8",ssl=ssl_set)
  File "C:\Python27\lib\site-packages\MySQLdb\__init__.py", line 81, in Connect
    return Connection(*args, **kwargs)
  File "C:\Python27\lib\site-packages\MySQLdb\connections.py", line 193, in __init__
    super(Connection, self).__init__(*args, **kwargs2)
OperationalError: (2026, 'SSL connection error')

ERROR:root:Traceback (most recent call last):
  File "D:/DC_MHA/db_handle/dbHandle.py", line 20, in __init__
    charset="utf8")
  File "C:\Python27\lib\site-packages\MySQLdb\__init__.py", line 81, in Connect
    return Connection(*args, **kwargs)
  File "C:\Python27\lib\site-packages\MySQLdb\connections.py", line 193, in __init__
    super(Connection, self).__init__(*args, **kwargs2)
OperationalError: (1045, "Access denied for user 'root'@'192.168.212.223' (using password: YES)")

